<?xml version="1.0"?>
<robot name="lynxmotion_AL5D">

  <link name="base_link">
    <visual>
      <geometry>
        <box size="0.5 0.5 .05"/>
      </geometry>
      <material name="black">
	      <color rgba="0 0 0 1" />
      </material>
	    <origin rpy="0 0 0" xyz="0 0 0"/>
    </visual>
    <collision>
      <geometry>
        <box size="0.5 0.5 .05"/>
      </geometry>
	    <origin rpy="0 0 0" xyz="0 0 0"/>
    </collision>
  </link>

  <joint name="servo1" type="fixed">
    <parent link="base_link"/>
    <child link="first_link"/>
    <origin xyz="0 0 0.025"/>
  </joint>  

  <link name="first_link">
    <visual>
      <geometry>
        <cylinder length="0.0562" radius="0.1"/>
      </geometry>
      <origin rpy="0 0 0" xyz="0 0 0.0281"/>
      <material name="blue">
	      <color rgba="0 0 0.8 1" />
      </material>
    </visual>
    <collision>
      <geometry>
        <cylinder length="0.0562" radius="0.1"/>
      </geometry>
      <origin rpy="0 0 0" xyz="0 0 0.0281"/>
    </collision>
  </link>

  <joint name="servo2_to_base" type="revolute">
  <axis xyz="0 0 1"/>
  <limit effort="1000.0" lower="-1.4" upper="1.4" velocity="0.5"/>
    <parent link="first_link"/>
    <child link="first_servo_h"/>
    <origin xyz="0 0 0.0562"/>
  </joint>

  <link name="first_servo_h">
    <visual>
      <geometry>
        <cylinder length="0.05" radius="0.02"/>
      </geometry>
	      <origin rpy="0 1.57075 0" xyz="0 0 0.02"/>
      <material name="green">
	      <color rgba="0 0.8 0 1" />
      </material>
    </visual>
  </link>

  <joint name="servo2" type="revolute">
    <axis xyz="1 0 0"/>
    <limit effort="1000.0" lower="0.0" upper="3.14159" velocity="0.5"/>
    <parent link="first_servo_h"/>
    <child link="second_link"/>
    <origin xyz="0 0 0.02"/>
  </joint>

  <link name="second_link">
    <visual>
      <geometry>
        <box size="0.05 0.04 0.10605"/>
      </geometry>
	    <origin rpy="0 0 0" xyz="0 0 0.073025"/>   <!--0.073025 = 0.10605/2 + 0.02(radius)-->
      <material name="blue" />
    </visual>
    <collision>
      <geometry>
        <box size="0.05 0.04 0.10605"/>
      </geometry>
	    <origin rpy="0 0 0" xyz="0 0 0.073025"/>
    </collision>
  </link>

  <joint name="link2_servo" type="fixed">
    <parent link="second_link"/>
    <child link="second_servo_h"/>
    <origin xyz="0 0 0.14605"/>
  </joint>

  <link name="second_servo_h">
    <visual>
      <geometry>
        <cylinder length="0.05" radius="0.02" />
      </geometry>
	    <origin rpy="0 1.57075 0" xyz="0 0 0"/>
	    <material name="green" />
    </visual>
  </link>

  <joint name="servo3" type="revolute">
    <axis xyz="1 0 0"/>
    <limit effort="1000.0" lower="0.0" upper="3.14159" velocity="0.5"/>
    <parent link="second_servo_h"/>
    <child link="third_link"/>
    <origin xyz="0 0 0"/>
  </joint>

  <link name="third_link">
    <visual>
      <geometry>
        <cylinder length="0.147325" radius="0.01" />  <!-- 0.147325/2 + 0.02 -->
      </geometry>
	    <origin rpy="1.57075 0 0" xyz="0 0.0936625 0"/>
	    <material name="white">
	      <color rgba="1 1 1 1" />
	    </material>
    </visual>
    <collision>
      <geometry>
        <cylinder length="0.147325" radius="0.01"  />
      </geometry>
	  <origin rpy="1.57075 0 0" xyz="0 0.0936625 0"/>
    </collision>
  </link>

  <joint name="link3_servo" type="fixed">
    <parent link="third_link"/>
    <child link="third_servo_h"/>
    <origin xyz="0 0.187325 0"/>
  </joint>

  <link name="third_servo_h">
    <visual>
      <geometry>
        <cylinder length="0.05" radius="0.02" />
      </geometry>
	  <origin rpy="0 1.57075 0" xyz="0 0 0"/>
	  <material name="green" />
    </visual>
  </link>

  <joint name="servo4" type="revolute">
    <axis xyz="1 0 0"/>
    <limit effort="1000.0" lower="0.0" upper="3.14159" velocity="0.5"/>
    <parent link="third_servo_h"/>
    <child link="fourth_servo_h"/>
    <origin xyz="0 0 0"/>
  </joint>
  
  <link name="fourth_servo_h">
    <visual>
      <geometry>
        <cylinder length="0.014" radius="0.02" />
      </geometry>
	    <origin rpy="1.57075 0 0" xyz="0 0.027 0"/>
	    <material name="blue" />
    </visual>
    <collision>
      <geometry>
        <cylinder length="0.014" radius="0.02" />
      </geometry>
	    <origin rpy="1.57075 0 0" xyz="0 0.027 0"/>
    </collision>
  </link>

  <joint name="servo5" type="revolute">
    <axis xyz="0 1 0"/>
    <limit effort="1000.0" lower="0.0" upper="3.14159" velocity="0.5"/>
    <parent link="fourth_servo_h"/>
    <child link="lbr_iiwa_with_wsg50__base_link"/>
    <origin xyz="0 0.0762 0"/>
  </joint>

  <!-- <link name="effector">
    <visual>
      <geometry>
        <sphere radius="0.025" />
      </geometry>
	<origin rpy="0 0 0" xyz="0 0 0"/>
	<material name="black" />
    </visual>
  </link> -->

  <!-- <joint name="effector_joint" type="fixed">
    <parent link="fourth_servo_h"/>
    <child link="effector"/>
    <origin xyz="-0.1 0 0" />
  </joint> -->

  <link name="lbr_iiwa_with_wsg50__base_link">
    <inertial>
      <mass value="0.2"/>
      <origin rpy="0  0  0" xyz="0  0  0"/>
      <inertia ixx="1" ixy="0" ixz="0" iyy="1" iyz="0" izz="1"/>
    </inertial>
    <collision name="lbr_iiwa_with_wsg50__base_link_collision">
      <origin rpy="0  0  0" xyz="0  0  0"/>
      <geometry>
        <box size="0.05 0.05 0.1"/>
      </geometry>
    </collision>
    <visual name="lbr_iiwa_with_wsg50__base_link_visual">
      <origin rpy="0  0  0" xyz="0  0  0"/>
      <geometry>
        <box size="0.05 0.05 0.1"/>
      </geometry>
    </visual>
  </link>
  <link name="lbr_iiwa_with_wsg50__left_finger">
    <inertial>
      <mass value="0.2"/>
      <origin rpy="0  0  0" xyz="0    0    0.04"/>
      <inertia ixx="0.1" ixy="0" ixz="0" iyy="0.1" iyz="0" izz="0.1"/>
    </inertial>
    <collision name="lbr_iiwa_with_wsg50__left_finger_collision">
      <origin rpy="0  0  0" xyz="0    0    0.04"/>
      <geometry>
        <box size="0.01 0.01 0.08"/>
      </geometry>
    </collision>
    <visual name="lbr_iiwa_with_wsg50__left_finger_visual">
      <origin rpy="0  0  0" xyz="0    0    0.04"/>
      <geometry>
        <box size="0.01 0.01 0.08"/>
      </geometry>
    </visual>
  </link>
  <link name="lbr_iiwa_with_wsg50__left_finger_base">
    <inertial>
      <mass value="0.2"/>
      <origin rpy="0  0  0" xyz="-0.003  0     0.04"/>
      <inertia ixx="0.1" ixy="0" ixz="0" iyy="0.1" iyz="0" izz="0.1"/>
    </inertial>
    <collision name="lbr_iiwa_with_wsg50__left_finger_base_collision">
      <origin rpy="0  0  0" xyz="0  0  0"/>
      <geometry>
        <mesh filename="meshes/finger_base_left.stl" scale="1 1 1"/>
      </geometry>
    </collision>
    <visual name="lbr_iiwa_with_wsg50__left_finger_base_visual">
      <origin rpy="0  0  0" xyz="0  0  0"/>
      <geometry>
        <mesh filename="meshes/finger_base_left.stl" scale="1 1 1"/>
      </geometry>
    </visual>
  </link>
  <link name="lbr_iiwa_with_wsg50__left_finger_tip">
    <inertial>
      <mass value="0.2"/>
      <origin rpy="0  0  0" xyz="-0.005  0     0.026"/>
      <inertia ixx="0.1" ixy="0" ixz="0" iyy="0.1" iyz="0" izz="0.1"/>
    </inertial>
    <collision name="lbr_iiwa_with_wsg50__left_finger_tip_collision">
      <origin rpy="0  0  0" xyz="0  0  0"/>
      <geometry>
        <mesh filename="meshes/finger_tip_left.stl" scale="1 1 1"/>
      </geometry>
    </collision>
    <visual name="lbr_iiwa_with_wsg50__left_finger_tip_visual">
      <origin rpy="0  0  0" xyz="0  0  0"/>
      <geometry>
        <mesh filename="meshes/finger_tip_left.stl" scale="1 1 1"/>
      </geometry>
    </visual>
  </link>
  <link name="lbr_iiwa_with_wsg50__right_finger">
    <inertial>
      <mass value="0.2"/>
      <origin rpy="0  0  0" xyz="0    0    0.04"/>
      <inertia ixx="0.1" ixy="0" ixz="0" iyy="0.1" iyz="0" izz="0.1"/>
    </inertial>
    <collision name="lbr_iiwa_with_wsg50__right_finger_collision">
      <origin rpy="0  0  0" xyz="0    0    0.04"/>
      <geometry>
        <box size="0.01 0.01 0.08"/>
      </geometry>
    </collision>
    <visual name="lbr_iiwa_with_wsg50__right_finger_visual">
      <origin rpy="0  0  0" xyz="0    0    0.04"/>
      <geometry>
        <box size="0.01 0.01 0.08"/>
      </geometry>
    </visual>
  </link>
  <link name="lbr_iiwa_with_wsg50__right_finger_base">
    <inertial>
      <mass value="0.2"/>
      <origin rpy="0  0  0" xyz="0.003  0     0.04"/>
      <inertia ixx="0.1" ixy="0" ixz="0" iyy="0.1" iyz="0" izz="0.1"/>
    </inertial>
    <collision name="lbr_iiwa_with_wsg50__right_finger_base_collision">
      <origin rpy="0  0  0" xyz="0  0  0"/>
      <geometry>
        <mesh filename="meshes/finger_base_right.stl" scale="1 1 1"/>
      </geometry>
    </collision>
    <visual name="lbr_iiwa_with_wsg50__right_finger_base_visual">
      <origin rpy="0  0  0" xyz="0  0  0"/>
      <geometry>
        <mesh filename="meshes/finger_base_right.stl" scale="1 1 1"/>
      </geometry>
    </visual>
  </link>
  <link name="lbr_iiwa_with_wsg50__right_finger_tip">
    <inertial>
      <mass value="0.2"/>
      <origin rpy="0  0  0" xyz="0.005  0     0.026"/>
      <inertia ixx="0.1" ixy="0" ixz="0" iyy="0.1" iyz="0" izz="0.1"/>
    </inertial>
    <collision name="lbr_iiwa_with_wsg50__right_finger_tip_collision">
      <origin rpy="0  0  0" xyz="0  0  0"/>
      <geometry>
        <mesh filename="meshes/finger_tip_right.stl" scale="1 1 1"/>
      </geometry>
    </collision>
    <visual name="lbr_iiwa_with_wsg50__right_finger_visual">
      <origin rpy="0  0  0" xyz="0  0  0"/>
      <geometry>
        <mesh filename="meshes/finger_tip_right.stl" scale="1 1 1"/>
      </geometry>
    </visual>
  </link>
  <joint name="lbr_iiwa_with_wsg50__base_left_finger_joint" type="revolute">
    <parent link="lbr_iiwa_with_wsg50__base_link"/>
    <child link="lbr_iiwa_with_wsg50__left_finger"/>
    <origin rpy="0   -0.05  0" xyz="0     0.024  0.045"/>
    <axis xyz="0  1  0"/>
    <limit effort="100.0" lower="-10.4" upper="10.01" velocity="0.0"/>
  </joint>
  <joint name="lbr_iiwa_with_wsg50__left_finger_base_joint" type="fixed">
    <parent link="lbr_iiwa_with_wsg50__left_finger"/>
    <child link="lbr_iiwa_with_wsg50__left_finger_base"/>
    <origin rpy="0   -0.25  0" xyz="-0.00099  0       0.08015"/>
    <axis xyz="0  0  0"/>
    <limit effort="0" lower="0" upper="0" velocity="0"/>
  </joint>
  <joint name="lbr_iiwa_with_wsg50__left_base_tip_joint" type="revolute">
    <parent link="lbr_iiwa_with_wsg50__left_finger_base"/>
    <child link="lbr_iiwa_with_wsg50__left_finger_tip"/>
    <origin rpy="0   0.5  0" xyz="0.0034   0       0.06175"/>
    <axis xyz="0  1  0"/>
    <limit effort="0.0" lower="-10.1" upper="10.3" velocity="0.0"/>
  </joint>
  <joint name="lbr_iiwa_with_wsg50__base_right_finger_joint" type="revolute">
    <parent link="lbr_iiwa_with_wsg50__base_link"/>
    <child link="lbr_iiwa_with_wsg50__right_finger"/>
    <origin rpy="0    0.05  0" xyz="0     0.024  0.045"/>
    <axis xyz="0  1  0"/>
    <limit effort="100.0" lower="-10.01" upper="10.4" velocity="0.0"/>
  </joint>
  <joint name="lbr_iiwa_with_wsg50__right_finger_base_joint" type="fixed">
    <parent link="lbr_iiwa_with_wsg50__right_finger"/>
    <child link="lbr_iiwa_with_wsg50__right_finger_base"/>
    <origin rpy="0    0.25  0" xyz="0.00099  0       0.08015"/>
    <axis xyz="0  0  0"/>
    <limit effort="0" lower="0" upper="0" velocity="0"/>
  </joint>
  <joint name="lbr_iiwa_with_wsg50__right_base_tip_joint" type="revolute">
    <parent link="lbr_iiwa_with_wsg50__right_finger_base"/>
    <child link="lbr_iiwa_with_wsg50__right_finger_tip"/>
    <origin rpy="0  -0.5  0" xyz="-0.0034   0       0.06175"/>
    <axis xyz="0  1  0"/>
    <limit effort="0.0" lower="-10.3" upper="10.1" velocity="0.0"/>
  </joint>
</robot>